2024-09-02 at 21:10:16 | ERROR | Проверка чека не пройдена для пожертвования ID: 8. Сообщение: Сумма в чеке не соответствует введенной сумме
2024-09-04 at 04:50:24 | ERROR | Signal handler <bound method DjangoFixup.on_import_modules of <celery.fixups.django.DjangoFixup object at 0xffffa55da050>> raised: SyntaxError('invalid syntax', ('/app/main/admin.py', 1, 20, 'from django.contrib\n', 1, 20))
Traceback (most recent call last):
  File "/usr/local/lib/python3.11/site-packages/celery/utils/dispatch/signal.py", line 276, in send
    response = receiver(signal=self, sender=sender, **named)
               ^^^^^^^^^^^^^^^^^^^^^^^^^^^^^^^^^^^^^^^^^^^^^
  File "/usr/local/lib/python3.11/site-packages/celery/fixups/django.py", line 100, in on_import_modules
    self.worker_fixup.validate_models()
  File "/usr/local/lib/python3.11/site-packages/celery/fixups/django.py", line 138, in validate_models
    self.django_setup()
  File "/usr/local/lib/python3.11/site-packages/celery/fixups/django.py", line 134, in django_setup
    django.setup()
  File "/usr/local/lib/python3.11/site-packages/django/__init__.py", line 24, in setup
    apps.populate(settings.INSTALLED_APPS)
  File "/usr/local/lib/python3.11/site-packages/django/apps/registry.py", line 124, in populate
    app_config.ready()
  File "/usr/local/lib/python3.11/site-packages/django/contrib/admin/apps.py", line 27, in ready
    self.module.autodiscover()
  File "/usr/local/lib/python3.11/site-packages/django/contrib/admin/__init__.py", line 52, in autodiscover
    autodiscover_modules("admin", register_to=site)
  File "/usr/local/lib/python3.11/site-packages/django/utils/module_loading.py", line 58, in autodiscover_modules
    import_module("%s.%s" % (app_config.name, module_to_search))
  File "/usr/local/lib/python3.11/importlib/__init__.py", line 126, in import_module
    return _bootstrap._gcd_import(name[level:], package, level)
           ^^^^^^^^^^^^^^^^^^^^^^^^^^^^^^^^^^^^^^^^^^^^^^^^^^^^
  File "<frozen importlib._bootstrap>", line 1204, in _gcd_import
  File "<frozen importlib._bootstrap>", line 1176, in _find_and_load
  File "<frozen importlib._bootstrap>", line 1147, in _find_and_load_unlocked
  File "<frozen importlib._bootstrap>", line 690, in _load_unlocked
  File "<frozen importlib._bootstrap_external>", line 936, in exec_module
  File "<frozen importlib._bootstrap_external>", line 1074, in get_code
  File "<frozen importlib._bootstrap_external>", line 1004, in source_to_code
  File "<frozen importlib._bootstrap>", line 241, in _call_with_frames_removed
  File "/app/main/admin.py", line 1
    from django.contrib
                       ^
SyntaxError: invalid syntax
2024-09-04 at 04:50:24 | ERROR | Signal handler <bound method DjangoFixup.on_import_modules of <celery.fixups.django.DjangoFixup object at 0xffffa8eddb90>> raised: SyntaxError('invalid syntax', ('/app/main/admin.py', 1, 20, 'from django.contrib\n', 1, 20))
Traceback (most recent call last):
  File "/usr/local/lib/python3.11/site-packages/celery/utils/dispatch/signal.py", line 276, in send
    response = receiver(signal=self, sender=sender, **named)
               ^^^^^^^^^^^^^^^^^^^^^^^^^^^^^^^^^^^^^^^^^^^^^
  File "/usr/local/lib/python3.11/site-packages/celery/fixups/django.py", line 100, in on_import_modules
    self.worker_fixup.validate_models()
  File "/usr/local/lib/python3.11/site-packages/celery/fixups/django.py", line 138, in validate_models
    self.django_setup()
  File "/usr/local/lib/python3.11/site-packages/celery/fixups/django.py", line 134, in django_setup
    django.setup()
  File "/usr/local/lib/python3.11/site-packages/django/__init__.py", line 24, in setup
    apps.populate(settings.INSTALLED_APPS)
  File "/usr/local/lib/python3.11/site-packages/django/apps/registry.py", line 124, in populate
    app_config.ready()
  File "/usr/local/lib/python3.11/site-packages/django/contrib/admin/apps.py", line 27, in ready
    self.module.autodiscover()
  File "/usr/local/lib/python3.11/site-packages/django/contrib/admin/__init__.py", line 52, in autodiscover
    autodiscover_modules("admin", register_to=site)
  File "/usr/local/lib/python3.11/site-packages/django/utils/module_loading.py", line 58, in autodiscover_modules
    import_module("%s.%s" % (app_config.name, module_to_search))
  File "/usr/local/lib/python3.11/importlib/__init__.py", line 126, in import_module
    return _bootstrap._gcd_import(name[level:], package, level)
           ^^^^^^^^^^^^^^^^^^^^^^^^^^^^^^^^^^^^^^^^^^^^^^^^^^^^
  File "<frozen importlib._bootstrap>", line 1204, in _gcd_import
  File "<frozen importlib._bootstrap>", line 1176, in _find_and_load
  File "<frozen importlib._bootstrap>", line 1147, in _find_and_load_unlocked
  File "<frozen importlib._bootstrap>", line 690, in _load_unlocked
  File "<frozen importlib._bootstrap_external>", line 936, in exec_module
  File "<frozen importlib._bootstrap_external>", line 1074, in get_code
  File "<frozen importlib._bootstrap_external>", line 1004, in source_to_code
  File "<frozen importlib._bootstrap>", line 241, in _call_with_frames_removed
  File "/app/main/admin.py", line 1
    from django.contrib
                       ^
SyntaxError: invalid syntax
